Workbook

Sheet Backlog
A1: ID | B1: Tipo | C1: Título / Elemento | D1: Objetivos | E1: Prioridad | F1: Esfuerzo estimado (h) | G1: Esfuerzo real (h) | H1: Criterios de aceptación / entregables | I1: Estado | J1: Etapa
A2: EP-01 | B2: Épica | C2: Etapa 1: Definición, investigación y análisis de requerimientos | D2: OG, OE1, OE2, OE3, OE4 | E2: Alta | F2: =F3+F8+F12+F16+F22 -> 74 | G2: =G3+G8+G12+G16+G22 -> 73 | H2: Problema, estado del arte, objetivos, requerimientos y alternativas definidos y respaldados. | I2: Realizado | J2: Etapa 1
A3: HU-01 | B3: Historia | C3: Investigación bibliográfica y estado del arte | D3: OG, OE1, OE2, OE4 | E3: Alta | F3: =SUM(F4:F7) -> 19 | G3: =SUM(G4:G7) -> 20 | H3: Conjunto de fuentes académicas y técnicas organizado en BibTeX y utilizado en el informe. | I3: Realizado | J3: Etapa 1
A4: T-01.1 | B4: Tarea | C4: Investigar comparaciones de distribuciones ligeras de Kubernetes | D4: OE1, OE2 | E4: Alta | F4: 6 | G4: 8 | H4: Fichas bibliográficas sobre K3s, MicroK8s y métricas de CPU, memoria, throughput y latencia. | I4: Realizado | J4: Etapa 1
A5: T-01.2 | B5: Tarea | C5: Investigar mecanismos HA y almacenamiento de estado (etcd vs Dqlite) | D5: OE1, OE2 | E5: Alta | F5: 5 | G5: 5 | H5: Fichas sobre quórum, replicación, recuperación y diferencias arquitectónicas. | I5: Realizado | J5: Etapa 1
A6: T-01.3 | B6: Tarea | C6: Investigar observabilidad energética y niveles de medición | D6: OE2 | E6: Alta | F6: 5 | G6: 4 | H6: Antecedentes sobre Scaphandre, RAPL/powercap, Kepler y limitaciones de atribución energética. | I6: Realizado | J6: Etapa 1
A7: T-01.4 | B7: Tarea | C7: Investigar infraestructura IaaS y limitaciones de comparación energética | D7: OE4 | E7: Baja | F7: 3 | G7: 3 | H7: Fuentes NIST y/o literatura que delimiten la comparación local frente a nube pública. | I7: Realizado | J7: Etapa 1
A8: HU-02 | B8: Historia | C8: Redacción de problema, partes interesadas y brechas | D8: OG | E8: Alta | F8: =SUM(F9:F11) -> 12 | G8: =SUM(G9:G11) -> 12 | H8: Sección de introducción con problema, relevancia, stakeholders y brechas claramente articuladas. | I8: Realizado | J8: Etapa 1
A9: T-02.1 | B9: Tarea | C9: Redacción: Introducción y definición del problema | D9: OG | E9: Alta | F9: 5 | G9: 5 | H9: Problema formulado y justificado mediante literatura pertinente. | I9: Realizado | J9: Etapa 1
A10: T-02.2 | B10: Tarea | C10: Redacción: percepción de las partes interesadas basada en literatura | D10: OG | E10: Alta | F10: 3 | G10: 3 | H10: Necesidades de administradores, sostenibilidad/SRE e investigación explicitadas sin presentarlas como entrevistas. | I10: Realizado | J10: Etapa 1
A11: T-02.3 | B11: Tarea | C11: Redacción: brechas de investigación y pregunta de investigación | D11: OG, OE2, OE3, OE4 | E11: Alta | F11: 4 | G11: 4 | H11: Cuatro brechas y pregunta de investigación coherentes con el alcance. | I11: Realizado | J11: Etapa 1
A12: HU-03 | B12: Historia | C12: Definición de objetivos y trazabilidad | D12: OG, OE1, OE2, OE3, OE4 | E12: Alta | F12: =SUM(F13:F15) -> 11 | G12: =SUM(G13:G15) -> 11 | H12: Objetivo general, objetivos específicos, criterios SMART y trazabilidad alineados. | I12: Realizado | J12: Etapa 1
A13: T-03.1 | B13: Tarea | C13: Redacción y revisión del objetivo general y objetivos específicos | D13: OG, OE1, OE2, OE3, OE4 | E13: Alta | F13: 4 | G13: 4 | H13: Objetivos formulados con verbos verificables y alcance delimitado. | I13: Realizado | J13: Etapa 1
A14: T-03.2 | B14: Tarea | C14: Redacción de criterios SMART | D14: OG | E14: Alta | F14: 3 | G14: 3 | H14: Criterios Specific, Measurable, Achievable, Relevant y Time-bound documentados. | I14: Realizado | J14: Etapa 1
A15: T-03.3 | B15: Tarea | C15: Construcción y revisión de matriz de trazabilidad | D15: OG, OE1, OE2, OE3, OE4 | E15: Alta | F15: 4 | G15: 4 | H15: Cada brecha vinculada con objetivos e indicadores de cumplimiento. | I15: Realizado | J15: Etapa 1
A16: HU-04 | B16: Historia | C16: Análisis y justificación de requerimientos | D16: OE1, OE2, OE3, OE4 | E16: Alta | F16: =SUM(F17:F21) -> 17 | G16: =SUM(G17:G21) -> 15 | H16: Requerimientos funcionales, no funcionales y experimentales documentados y justificados. | I16: Realizado | J16: Etapa 1
A17: T-04.1 | B17: Tarea | C17: Redacción de requerimientos de arquitectura, HA y VIP | D17: OE1 | E17: Alta | F17: 3 | G17: 3 | H17: RF-01 a RF-05 formulados con criterios de aceptación verificables. | I17: Realizado | J17: Etapa 1
A18: T-04.2 | B18: Tarea | C18: Redacción de requerimientos de automatización y reproducibilidad | D18: OE1 | E18: Alta | F18: 3 | G18: 3 | H18: RNF-01 a RNF-04 definidos para Terraform, Ansible, homogeneidad y versionado. | I18: Realizado | J18: Etapa 1
A19: T-04.3 | B19: Tarea | C19: Redacción de requerimientos de observabilidad energética | D19: OE2 | E19: Alta | F19: 4 | G19: 3 | H19: RE-01 a RE-04 definidos con nivel de medición explícito. | I19: Realizado | J19: Etapa 1
A20: T-04.4 | B20: Tarea | C20: Redacción de requerimientos de observabilidad de recursos y rendimiento | D20: OE2, OE3 | E20: Alta | F20: 5 | G20: 4 | H20: RO-01 a RO-08 definidos para CPU, RAM, Prometheus, throughput, latencia, errores y sincronización. | I20: Realizado | J20: Etapa 1
A21: T-04.5 | B21: Tarea | C21: Redacción de requerimientos de experimentación, resiliencia y nube pública | D21: OE2, OE3, OE4 | E21: Alta | F21: 2 | G21: 2 | H21: REX-01 a REX-07, RR-01 a RR-04 y RC-01 a RC-03 definidos. | I21: Realizado | J21: Etapa 1
A22: HU-05 | B22: Historia | C22: Evaluación crítica de alternativas técnicas | D22: OE1, OE2 | E22: Alta | F22: =SUM(F23:F27) -> 15 | G22: =SUM(G23:G27) -> 15 | H22: Alternativas técnicas comparadas y decisión final justificada. | I22: Realizado | J22: Etapa 1
A23: T-05.1 | B23: Tarea | C23: Comparar K3s/MicroK8s frente a Kubernetes estándar | D23: OE1 | E23: Media | F23: 3 | G23: 3 | H23: Alcance de dos distribuciones ligeras justificado. | I23: Realizado | J23: Etapa 1
A24: T-05.2 | B24: Tarea | C24: Comparar Scaphandre frente a alternativas de observabilidad energética | D24: OE2 | E24: Alta | F24: 3 | G24: 3 | H24: Selección de medición a nivel de host justificada, sin atribución innecesaria a contenedores. | I24: Realizado | J24: Etapa 1
A25: T-05.3 | B25: Tarea | C25: Justificar Node Exporter y Prometheus para recursos | D25: OE2 | E25: Alta | F25: 3 | G25: 3 | H25: Separación clara entre energía, utilización de recursos y almacenamiento temporal. | I25: Realizado | J25: Etapa 1
A26: T-05.4 | B26: Tarea | C26: Justificar k6 para carga y métricas de rendimiento | D26: OE2 | E26: Alta | F26: 3 | G26: 3 | H26: Selección de herramienta respaldada por sus métricas de solicitudes, duración y errores. | I26: Realizado | J26: Etapa 1
A27: T-05.5 | B27: Tarea | C27: Justificar Keepalived/VRRP y Terraform/Ansible | D27: OE1 | E27: Media | F27: 3 | G27: 3 | H27: Decisiones de acceso redundante y automatización justificadas. | I27: Realizado | J27: Etapa 1
A28: EP-02 | B28: Épica | C28: Etapa 2: Diseño experimental y técnico | D28: OE1, OE2, OE3 | E28: Alta | F28: =F29+F34+F40+F46 -> 40 | G28: =G29+G34+G40+G46 -> 33 | H28: Diseño de arquitectura, instrumentación, protocolo, datos y documentación listos para implementar. | I28: Realizado | J28: Etapa 2
A29: HU-06 | B29: Historia | C29: Diseño de infraestructura virtualizada y red | D29: OE1 | E29: Alta | F29: =SUM(F30:F33) -> 10 | G29: =SUM(G30:G33) -> 10 | H29: Diseño reproducible de 6 VMs, red, VIP y recursos homogéneos. | I29: Realizado | J29: Etapa 2
A30: T-06.1 | B30: Tarea | C30: Diseñar topología QEMU/KVM para 6 VMs | D30: OE1 | E30: Alta | F30: 2 | G30: 2 | H30: Diagrama con 3 nodos K3s y 3 nodos MicroK8s y recursos equivalentes. | I30: Realizado | J30: Etapa 2
A31: T-06.2 | B31: Tarea | C31: Definir CPU, RAM, almacenamiento y sistema operativo homogéneos | D31: OE1 | E31: Alta | F31: 3 | G31: 3 | H31: Especificaciones técnicas registradas como referencia experimental. | I31: Realizado | J31: Etapa 2
A32: T-06.3 | B32: Tarea | C32: Diseñar direccionamiento, redes y VIP | D32: OE1 | E32: Alta | F32: 3 | G32: 3 | H32: Plan de direccionamiento documentado con IPs de nodos y VIP. | I32: Realizado | J32: Etapa 2
A33: T-06.4 | B33: Tarea | C33: Actualizar justificación del mecanismo VIP: de Keepalived/VRRP a kube-vip | D33: OE1 | E33: Media | F33: 2 | G33: 2 | H33: informe actualizado con la justificación de kube-vip. | I33: Realizado | J33: Etapa 2
A34: HU-07 | B34: Historia | C34: Diseño de la arquitectura de observabilidad | D34: OE2 | E34: Alta | F34: =SUM(F35:F39) -> 15 | G34: =SUM(G35:G39) -> 10 | H34: Fuentes, flujo de datos y responsabilidades de cada herramienta definidos. | I34: Realizado | J34: Etapa 2
A35: T-07.1 | B35: Tarea | C35: Diseñar medición energética con Scaphandre + RAPL/powercap | D35: OE2 | E35: Alta | F35: 3 | G35: 2 | H35: Fuente energética, dominio y ventana de medición definidos. | I35: Realizado | J35: Etapa 2
A36: T-07.2 | B36: Tarea | C36: Diseñar recolección de CPU y RAM con Node Exporter | D36: OE2 | E36: Alta | F36: 3 | G36: 2 | H36: Métricas y frecuencia de consulta seleccionadas. | I36: Realizado | J36: Etapa 2
A37: T-07.3 | B37: Tarea | C37: Diseñar almacenamiento y consultas en Prometheus | D37: OE2 | E37: Alta | F37: 3 | G37: 2 | H37: Métricas, etiquetas y retención necesarias definidas. | I37: Realizado | J37: Etapa 2
A38: T-07.4 | B38: Tarea | C38: Diseñar instrumentación de rendimiento con k6 | D38: OE2 | E38: Alta | F38: 3 | G38: 2 | H38: Métricas de throughput, latencia, errores y resultados definidas. | I38: Realizado | J38: Etapa 2
A39: T-07.5 | B39: Tarea | C39: Diseñar observación de resiliencia y sincronización temporal | D39: OE2, OE3 | E39: Alta | F39: 3 | G39: 2 | H39: Eventos, logs, marcas temporales y criterios de inicio/recuperación definidos. | I39: Realizado | J39: Etapa 2
A40: HU-08 | B40: Historia | C40: Diseño del protocolo experimental | D40: OE2, OE3 | E40: Alta | F40: =SUM(F41:F45) -> 9 | G40: =SUM(G41:G45) -> 8 | H40: Matriz de escenarios, repeticiones, ventanas y criterios de calidad aprobada. | I40: Realizado | J40: Etapa 2
...

Sheet Resumen
A1: Etapa | B1: Fecha evaluación | C1: Foco principal | D1: Horas estimadas | E1: Horas reales | F1: Tareas totales | G1: Tareas realizadas
A2: Etapa 1 | B2: 46269 | C2: Problema, investigación, objetivos y requerimientos | D2: =SUMIFS(Backlog!F:F,Backlog!B:B,"Tarea",Backlog!J:J,A2) -> 74 | E2: =SUMIFS(Backlog!G:G,Backlog!B:B,"Tarea",Backlog!J:J,A2) -> 73 | F2: =COUNTIFS(Backlog!B:B,"Tarea",Backlog!J:J,A2) -> 20 | G2: =COUNTIFS(Backlog!B:B,"Tarea",Backlog!J:J,A2,Backlog!I:I,"Realizado") -> 20
A3: Etapa 2 | B3: 46297 | C3: Diseño técnico, arquitectura, protocolo e implementación inicial | D3: =SUMIFS(Backlog!F:F,Backlog!B:B,"Tarea",Backlog!J:J,A3) -> 74 | E3: =SUMIFS(Backlog!G:G,Backlog!B:B,"Tarea",Backlog!J:J,A3) -> 77 | F3: =COUNTIFS(Backlog!B:B,"Tarea",Backlog!J:J,A3) -> 43 | G3: =COUNTIFS(Backlog!B:B,"Tarea",Backlog!J:J,A3,Backlog!I:I,"Realizado") -> 43
A4: Etapa 3 | B4: 46325 | C4: Implementación observabilidad, pruebas piloto y validación preliminar | D4: =SUMIFS(Backlog!F:F,Backlog!B:B,"Tarea",Backlog!J:J,A4) -> 115 | E4: =SUMIFS(Backlog!G:G,Backlog!B:B,"Tarea",Backlog!J:J,A4) -> 67 | F4: =COUNTIFS(Backlog!B:B,"Tarea",Backlog!J:J,A4) -> 47 | G4: =COUNTIFS(Backlog!B:B,"Tarea",Backlog!J:J,A4,Backlog!I:I,"Realizado") -> 35
A5: Etapa 4 | B5: 46360 | C5: Campaña definitiva, análisis, informe final y defensa | D5: =SUMIFS(Backlog!F:F,Backlog!B:B,"Tarea",Backlog!J:J,A5) -> 122 | E5: =SUMIFS(Backlog!G:G,Backlog!B:B,"Tarea",Backlog!J:J,A5) -> 0 | F5: =COUNTIFS(Backlog!B:B,"Tarea",Backlog!J:J,A5) -> 25 | G5: =COUNTIFS(Backlog!B:B,"Tarea",Backlog!J:J,A5,Backlog!I:I,"Realizado") -> 0
A7: Indicador | B7: Valor
A8: Total de horas estimadas (tareas) | B8: =SUM(D2:D5) -> 385
A9: Total de horas reales (tareas) | B9: =SUM(E2:E5) -> 217
A10: Tareas totales | B10: =SUM(F2:F5) -> 135
A11: Tareas realizadas | B11: =SUM(G2:G5) -> 98
